

Generating train split: 100%|██████████| 9469/9469 [00:05<00:00, 1852.42 examples/s]

Generating validation split: 100%|██████████| 3925/3925 [00:02<00:00, 1874.41 examples/s]
DatasetDict({
    train: Dataset({
        features: ['image', 'label'],
        num_rows: 9469
    })
    validation: Dataset({
        features: ['image', 'label'],
        num_rows: 3925
    })
})
<train label> 2: 993
<train label> 0: 963
<train label> 3: 858
<train label> 4: 941
<train label> 9: 960
<train label> 7: 931
<train label> 1: 955
<train label> 8: 951
<train label> 6: 961
<train label> 5: 956
<test label> 2: 357
<test label> 0: 387
<test label> 3: 386
<test label> 4: 409
<test label> 9: 390
<test label> 7: 419
<test label> 1: 395
<test label> 8: 399
<test label> 6: 389
<test label> 5: 394
/home/hail09/anaconda3/envs/venv_ImagenNet10/lib/python3.9/site-packages/torchvision/models/_utils.py:208: UserWarning: The parameter 'pretrained' is deprecated since 0.13 and may be removed in the future, please use 'weights' instead.
  warnings.warn(
/home/hail09/anaconda3/envs/venv_ImagenNet10/lib/python3.9/site-packages/torchvision/models/_utils.py:223: UserWarning: Arguments other than a weight enum or `None` for 'weights' are deprecated since 0.13 and may be removed in the future. The current behavior is equivalent to passing `weights=None`.
  warnings.warn(msg)
/home/hail09/anaconda3/envs/venv_ImagenNet10/lib/python3.9/site-packages/torch/cuda/__init__.py:141: UserWarning: CUDA initialization: Unexpected error from cudaGetDeviceCount(). Did you run some cuda functions before calling NumCudaDevices() that might have already set an error? Error 804: forward compatibility was attempted on non supported HW (Triggered internally at ../c10/cuda/CUDAFunctions.cpp:108.)
  return torch._C._cuda_getDeviceCount() > 0
Traceback (most recent call last):
  File "/home/hail09/Documents/hail_moon/ImageNet10_experiments/download&check_dataset.py", line 288, in <module>
    test_major_acc = test(resnet_model, test_major_classes, device)
  File "/home/hail09/Documents/hail_moon/ImageNet10_experiments/download&check_dataset.py", line 234, in test
    outputs = model(images.to('cuda'))
  File "/home/hail09/anaconda3/envs/venv_ImagenNet10/lib/python3.9/site-packages/torch/cuda/__init__.py", line 302, in _lazy_init
    torch._C._cuda_init()
RuntimeError: Unexpected error from cudaGetDeviceCount(). Did you run some cuda functions before calling NumCudaDevices() that might have already set an error? Error 804: forward compatibility was attempted on non supported HW